<!DOCTYPE html>
<html lang="en">
<head>
    <meta  charset="UTF-8">
    <meta name="viewport" content="width=device-width, initial-scale=1.0">
    <title>Document</title>
</head>
<body style="background-color: #212121; color: beige;">
    <a style="color: beige;" href="https://developer.mozilla.org/en-US/docs/Web/JavaScript/Reference/Global_Objects/Promise">Promise-Read more</a>



    <script>
        // the callback function of Promise have two parts resolve and reject
        const promiseOne = new Promise((resolve, reject)=>{
            setTimeout(() => {
                // do an Async task
                // DB call, cryptography, network
                console.log("Async tack is completed");
                // we need to call the resolve methode here, only then the .then function will connect with the resolve argument
                resolve();
            }, 1000);
        })

        // this .then function will automatically receive an argument that whatever work is happenen in the main function will get returned to this .then function
        promiseOne.then(()=>{
            console.log('Promise consumed');
        })



        new Promise((resolve, reject)=>{
            setTimeout(()=>{
                console.log("Async task 2");
                resolve();
            },1000)
        }).then(()=>{
            console.log("Async task 2 consumed");
        })



        const promiseThree = new Promise((resolve, reject)=>{
            setTimeout(()=>{
                resolve({
                    userName : "Pratap",
                    email : "pratap@example.com"
                })
            },1000)
        })

        promiseThree.then((anything)=>{
            console.log(anything);
            console.log(anything.userName);
        })



        const poromiseFour = new Promise((resolve, reject)=>{
            setTimeout(() => {
                
                
                // let anythingError = false;
                let anythingError = true;


                if(!anythingError){
                    resolve({
                        userName : "Pratap",
                        password : 123
                    })
                } 
                else{
                    reject("ERROR: Something went wrong!")
                }
            }, 1000);
        })

        poromiseFour.then((user)=>{
            // this return will go to the next .then
            return user;
        }).then((anything)=>{
            console.log(anything.password);
        }).catch((someError)=>{
            console.log(someError);
        }).finally(()=>{
            // this finally is default
            console.log("The Promise is either resolve or rejected");
        })




        // normal async await  here we are not handelling the error correctly

        const promiseFive = new Promise((resolve, reject)=>{
            let error = false;
            setTimeout(() => {
                if(!error){
                    resolve({
                    userName  : "Soem Name",
                    password : "Some Passwor"
                })
                }
                else{
                    reject("ERROR: some error has occure")
                }
            }, 1000);
        })

        const consumePromiseFive = async()=>{
            const someResponse = await promiseFive;
            console.log(someResponse);
        }

        consumePromiseFive();

         

        // here using async await function with try and catch we are handelling the error correctly

        const promiseSix = new Promise((resolve, reject)=>{
            
            
            // let error = false;
            let error = true;



            setTimeout(() => {
                if(!error){
                    resolve({
                        userName : "New Name",
                        password : "New Password"
                    })
                }
                else{
                    reject("ERROR: some new error has occure");
                }
            }, 1000);
        }) 


        const consumePromiseSix = async()=>{
            try{
                const someResponse = await promiseSix;
                console.log(someResponse);
            }
            catch(error){
                console.log(error);
            }
        }

        consumePromiseSix();





        // fetch an url using fetch and try catch
        const getAllUsers = async()=>{
            try{
                const response = await fetch('https://jsonplaceholder.typicode.com/users');
                // console.log(response);
                const data = await response.json()
                console.log(data);
            }
            catch(e){
                console.log('error',e );
            }
        }

        getAllUsers();



        
        // fetch an url using then and catch\

        fetch('https://jsonplaceholder.typicode.com/users').then((response)=>{
            return response.json();
        }).then((data)=>{
            console.log(data);
        }).catch((error)=>{
            console.log("Error!");
        })


    </script>
</body>
</html> 